<?xml version="1.0"?>

<robot name="robocov">

  <!-- Color of materials -->
  <material name="yellow">
    <color rgba="1 1 0 1"/>
  </material>
  <material name="blue">
    <color rgba="0 0 1 1"/>
  </material>
  <material name="red">
    <color rgba="1 0 0 1"/>
  </material>
  <material name="magenta">
    <color rgba="1 0 1 1"/>
  </material>
  <material name="cyan">
    <color rgba="0 1 1 1"/>
  </material>
  <material name="gray">
    <color rgba="0.5 0.5 0.5 1"/>
  </material>
  <material name="black">
    <color rgba="0 0 0 1"/>
  </material>

  <!-- Riel -->
  <link name="base_link">
    <visual>
      <geometry>
        <box size="0.05 1 0.02"/>
      </geometry>
      <origin rpy="0 0 0" xyz="0 0 0"/>
      <material name="yellow" />
    </visual>
    <inertial>
        <mass value="4.0"/>
        <origin rpy="0 0 0" xyz="0 0 0"/>
        <inertia ixx="0.3335" ixy="0.0" ixz="0.0" iyy="0.0010" iyz="0.0" izz="0.3342"/>
    </inertial>
  </link>

  <!-- Union entre Riel y Base de Robot -->
  <joint name="joint1" type="prismatic">
    <parent link="base_link"/>
    <child link="link1"/>
    <origin xyz="0 0 0.01"/>
    <axis xyz="0 1 0" />
    <limit effort="300" velocity="0.1" lower="-0.426" upper="0.426"/>
  </joint>

  <!-- Link1 -->
  <link name="link1">
    <visual>
      <geometry>
        <cylinder length="0.185" radius="0.074"/>
      </geometry>
      <origin rpy="0 0 0" xyz="0 0 0.0925"/>
      <material name="blue" />
    </visual>
    <inertial>
        <mass value="3.7"/>
        <origin rpy="0 0 0" xyz="0 0 0.0925"/>
        <inertia ixx="0.0156" ixy="0.0" ixz="0.0" iyy="0.0156" iyz="0.0" izz="0.0101"/>
    </inertial>
  </link>
  
  <!-- Union entre codo_link1 y link1 -->
  <joint name="un_codo_link1" type="fixed">
    <parent link="link1"/>
    <child link="codo_link1"/>
    <origin xyz="0 0 0"/>
  </joint>
 
  <!-- codo_link1 -->
  <link name="codo_link1">
    <visual>
      <geometry>
        <sphere radius="0.074" />
      </geometry>
      <origin rpy="0 0 0" xyz="0 0 0.185"/>
      <material name="blue" />
    </visual>
    <inertial>
        <mass value="1"/>
        <origin rpy="0 0 0" xyz="0 0 0.185"/>
        <inertia ixx="0.022" ixy="0.0" ixz="0.0" iyy="0.022" iyz="0.0" izz="0.022"/>
    </inertial>
  </link>

<!-- Union entre soporte_izq y Riel -->
  <joint name="un_izq" type="fixed">
    <parent link="base_link"/>
    <child link="soporte_izq"/>
    <origin xyz="0 0.5 0"/>
  </joint>

<!-- soporte_izq -->
  <link name="soporte_izq">
    <visual>
      <geometry>
        <box size="0.2 0.1 0.1"/>
      </geometry>
      <origin rpy="0 0 0" xyz="0 0.05 0"/>
      <material name="blue" />
    </visual>
    <inertial>
        <mass value="1"/>
        <origin rpy="0 0 0" xyz="0 0.05 0"/>
        <inertia ixx="0.0017" ixy="0.0" ixz="0.0" iyy="0.0042" iyz="0.0" izz="0.0042"/>
    </inertial>
  </link>

<!-- Union entre soporte_der y Riel -->
  <joint name="un_der" type="fixed">
    <parent link="base_link"/>
    <child link="soporte_der"/>
    <origin xyz="0 -0.5 0"/>
  </joint>

<!-- soporte_der -->
  <link name="soporte_der">
    <visual>
      <geometry>
        <box size="0.2 0.1 0.1"/>
      </geometry>
      <origin rpy="0 0 0" xyz="0 -0.05 0"/>
      <material name="blue" />
    </visual>
    <inertial>
        <mass value="1"/>
        <origin rpy="0 0 0" xyz="0 -0.05 0"/>
        <inertia ixx="0.0017" ixy="0.0" ixz="0.0" iyy="0.0042" iyz="0.0" izz="0.0042"/>
    </inertial>
  </link>

  <!-- Union entre link1 y link2-->
  <joint name="joint2" type="revolute">
    <parent link="link1"/>
    <child link="link2"/>
    <origin xyz="0 0.074 0.185"/>
    <axis xyz="0 1 0" />
    <limit effort="300" velocity="0.1" lower="-2.1" upper="2.1"/>
  </joint>
  
  <!-- link2-->
  <link name="link2">
    <visual>
      <geometry>
        <cylinder length="0.410" radius="0.074"/>
      </geometry>
      <origin rpy="0 0 0" xyz="0 0.074 0.205"/>
      <material name="cyan" />
    </visual>
    <inertial>
        <mass value="5"/>
        <origin rpy="0 0 0" xyz="0 0.074 0.205"/>
        <inertia ixx="0.0769" ixy="0.0" ixz="0.0" iyy="0.0769" iyz="0.0" izz="0.0137"/>
    </inertial>
  </link>
  
    <!-- Union entre codo_link2 y link2 -->
  <joint name="un_codo_link2" type="fixed">
    <parent link="link2"/>
    <child link="codo_link2"/>
    <origin xyz="0 0 0"/>
  </joint>
 
  <!--codo_link2 -->
  <link name="codo_link2">
    <visual>
      <geometry>
        <sphere radius="0.074" />
      </geometry>
      <origin rpy="0 0 0" xyz="0 0.074 0"/>
      <material name="cyan" />
    </visual>
    <inertial>
        <mass value="1"/>
        <origin rpy="0 0 0" xyz="0 0.074 0"/>
        <inertia ixx="0.022" ixy="0.0" ixz="0.0" iyy="0.022" iyz="0.0" izz="0.022"/>
    </inertial>
  </link>

  <!-- Union entre codo_link3 y link2 -->
  <joint name="un_codo_link3" type="fixed">
    <parent link="link2"/>
    <child link="codo_link3"/>
    <origin xyz="0 0 0"/>
  </joint>
 
  <!--codo_link3 -->
  <link name="codo_link3">
    <visual>
      <geometry>
        <sphere radius="0.074" />
      </geometry>
      <origin rpy="0 0 0" xyz="0 0.074 0.410"/>
      <material name="cyan" />
    </visual>
    <inertial>
        <mass value="1"/>
        <origin rpy="0 0 0" xyz="0 0.074 0.410"/>
        <inertia ixx="0.022" ixy="0.0" ixz="0.0" iyy="0.022" iyz="0.0" izz="0.022"/>
    </inertial>
  </link>
  
  <!-- Union entre link2 y link3-->
  <joint name="joint3" type="revolute">
    <parent link="link2"/>
    <child link="link3"/>
    <origin xyz="0 0.074 0.410"/>
    <axis xyz="0 1 0" />
    <limit effort="300" velocity="0.1" lower="-1.5708" upper="1.508"/>
  </joint>

  <!--link3 -->
  <link name="link3">
    <visual>
      <geometry>
        <sphere radius="0.074" />
      </geometry>
      <origin rpy="0 0 0" xyz="0 -0.148 0"/>
      <material name="magenta" />
    </visual>
    <inertial>
        <mass value="1"/>
        <origin rpy="0 0 0" xyz="0 -0.148 0"/>
        <inertia ixx="0.022" ixy="0.0" ixz="0.0" iyy="0.022" iyz="0.0" izz="0.022"/>
    </inertial>
  </link>
  
  <!-- Union entre link3 y link4 -->
  <joint name="joint4" type="revolute">
    <parent link="link3"/>
    <child link="link4"/>
    <origin xyz="0 -0.148 0"/>
    <axis xyz="0 0 -1" />
    <limit effort="300" velocity="0.1" lower="-1.5708" upper="1.508"/>
  </joint>

  <!-- link4-->
  <link name="link4">
    <visual>
      <geometry>
        <cylinder length="0.430" radius="0.074"/>
      </geometry>
      <origin rpy="0 0 0" xyz="0 0 0.215"/>
      <material name="red" />
    </visual>
    <inertial>
        <mass value="5"/>
        <origin rpy="0 0 0" xyz="0 0 0.215"/>
        <inertia ixx="0.0839" ixy="0.0" ixz="0.0" iyy="0.0839" iyz="0.0" izz="0.0137"/>
    </inertial>
  </link>
  

  <!-- Union entre codo_link5 y link4 -->
  <joint name="un_codo_link5" type="fixed">
    <parent link="link4"/>
    <child link="codo_link5"/>
    <origin xyz="0 0 0"/>
  </joint>
 
  <!--codo_link5 -->
  <link name="codo_link5">
    <visual>
      <geometry>
        <sphere radius="0.074" />
      </geometry>
      <origin rpy="0 0 0" xyz="0 0 0.430"/>
      <material name="red" />
    </visual>
    <inertial>
        <mass value="1"/>
        <origin rpy="0 0 0" xyz="0 0 0.430"/>
        <inertia ixx="0.0022" ixy="0.0" ixz="0.0" iyy="0.0022" iyz="0.0" izz="0.0022"/>
    </inertial>
  </link>
  
  <!-- Union entre link4 y link5-->
  <joint name="joint5" type="revolute">
    <parent link="link4"/>
    <child link="link5"/>
    <origin xyz="0 0.148 0.430"/>
    <axis xyz="0 1 0" />
    <limit effort="300" velocity="0.1" lower="-1.5708" upper="1.5708"/>
  </joint>

  <!--link5-->
  <link name="link5">
    <visual>
      <geometry>
        <cylinder length="0.074" radius="0.074"/>
      </geometry>
      <origin rpy="0 0 0" xyz="0 0 0.037"/>
      <material name="gray" />
    </visual>
    <inertial>
        <mass value="1"/>
        <origin rpy="0 0 0" xyz="0 0 0.037"/>
        <inertia ixx="0.0018" ixy="0.0" ixz="0.0" iyy="0.0018" iyz="0.0" izz="0.0027"/>
    </inertial>
  </link>
  
  <!-- Union entre codo_link6 y link5 -->
  <joint name="un_codo_link6" type="fixed">
    <parent link="link5"/>
    <child link="codo_link6"/>
    <origin xyz="0 0 0"/>
  </joint>

  <!--codo_link6-->
  <link name="codo_link6">
    <visual>
      <geometry>
        <sphere radius="0.074"/>
      </geometry>
      <origin rpy="0 0 0" xyz="0 0 0"/>
      <material name="gray" />
    </visual>
    <inertial>
        <mass value="1"/>
        <origin rpy="0 0 0" xyz="0 0 0"/>
        <inertia ixx="0.0022" ixy="0.0" ixz="0.0" iyy="0.0022" iyz="0.0" izz="0.0022"/>
    </inertial>
  </link>
 
  <!-- Union entre link5 y efector_final -->
  <joint name="joint6" type="revolute">
    <parent link="link5"/>
    <child link="efector_final"/>
    <origin xyz="0 0 0.0925"/>
    <axis xyz="0 0 1" />
    <limit effort="300" velocity="0.1" lower="-3.14" upper="3.14"/>
  </joint>

  <!--efector_final-->
  <link name="efector_final">
    <visual>
      <geometry>
        <box size="0.037 0.105 0.105"/>
      </geometry>
      <origin rpy="0 1.5708 0" xyz="0 0 0"/>
      <material name="black" />
    </visual>
    <!--inertial>
        <mass value="1"/>
        
        <inertia ixx="0.0018" ixy="0.0" ixz="0.0" iyy="0.0010" iyz="0.0" izz="0.0010"/>
    </inertial-->
  </link>
  
  
</robot>